INFO: [guild] Running trial 809a6ac4caf84347a6245a6b7a413305: TABL:train (attention_constraint=None, attention_regularizer=None, binarize=no, dev=no, dimensionality=100, horizon=1, learning_rate=0.001, n_bl_layers=2, n_tabl_layers=1, optimizer=adam, projection_constraint=None, projection_regularizer=None, remote=no, window=100)
Traceback (most recent call last):
  File "/home/blez/Projects/anomaly_simulation/Zoo/Results/runs/809a6ac4caf84347a6245a6b7a413305/.guild/sourcecode/TABL/train.py", line 78, in <module>
    _, train_y, _, test_y, train_generator, test_generator = aursad.get_dataset_generator(path=data_path,
  File "/home/blez/anaconda3/envs/anomaly_detection/lib/python3.8/site-packages/aursad/aursad.py", line 190, in get_dataset_generator
    data = load_dataset(path=path)
  File "/home/blez/anaconda3/envs/anomaly_detection/lib/python3.8/site-packages/aursad/utils.py", line 166, in load_dataset
    dataframe = pd.read_hdf(path)
  File "/home/blez/anaconda3/envs/anomaly_detection/lib/python3.8/site-packages/pandas/io/pytables.py", line 397, in read_hdf
    raise FileNotFoundError(f"File {path_or_buf} does not exist")
FileNotFoundError: File Data/AURSAD.h5 does not exist
ERROR: [guild] Trial 809a6ac4caf84347a6245a6b7a413305 exited with an error (1) - see log for details
INFO: [guild] Running trial 9496c9b775ed442f98c90560f748a241: TABL:train (attention_constraint=None, attention_regularizer=None, binarize=no, dev=no, dimensionality=80, horizon=1, learning_rate=0.001, n_bl_layers=2, n_tabl_layers=1, optimizer=adam, projection_constraint=None, projection_regularizer=None, remote=no, window=100)
Traceback (most recent call last):
  File "/home/blez/Projects/anomaly_simulation/Zoo/Results/runs/9496c9b775ed442f98c90560f748a241/.guild/sourcecode/TABL/train.py", line 78, in <module>
    _, train_y, _, test_y, train_generator, test_generator = aursad.get_dataset_generator(path=data_path,
  File "/home/blez/anaconda3/envs/anomaly_detection/lib/python3.8/site-packages/aursad/aursad.py", line 190, in get_dataset_generator
    data = load_dataset(path=path)
  File "/home/blez/anaconda3/envs/anomaly_detection/lib/python3.8/site-packages/aursad/utils.py", line 166, in load_dataset
    dataframe = pd.read_hdf(path)
  File "/home/blez/anaconda3/envs/anomaly_detection/lib/python3.8/site-packages/pandas/io/pytables.py", line 397, in read_hdf
    raise FileNotFoundError(f"File {path_or_buf} does not exist")
FileNotFoundError: File Data/AURSAD.h5 does not exist
ERROR: [guild] Trial 9496c9b775ed442f98c90560f748a241 exited with an error (1) - see log for details
INFO: [guild] Running trial 942b095459684db99ce76ca8ee4d49c6: TABL:train (attention_constraint=None, attention_regularizer=None, binarize=no, dev=no, dimensionality=40, horizon=1, learning_rate=0.001, n_bl_layers=2, n_tabl_layers=1, optimizer=adam, projection_constraint=None, projection_regularizer=None, remote=no, window=100)
Traceback (most recent call last):
  File "/home/blez/Projects/anomaly_simulation/Zoo/Results/runs/942b095459684db99ce76ca8ee4d49c6/.guild/sourcecode/TABL/train.py", line 78, in <module>
    _, train_y, _, test_y, train_generator, test_generator = aursad.get_dataset_generator(path=data_path,
  File "/home/blez/anaconda3/envs/anomaly_detection/lib/python3.8/site-packages/aursad/aursad.py", line 190, in get_dataset_generator
    data = load_dataset(path=path)
  File "/home/blez/anaconda3/envs/anomaly_detection/lib/python3.8/site-packages/aursad/utils.py", line 166, in load_dataset
    dataframe = pd.read_hdf(path)
  File "/home/blez/anaconda3/envs/anomaly_detection/lib/python3.8/site-packages/pandas/io/pytables.py", line 397, in read_hdf
    raise FileNotFoundError(f"File {path_or_buf} does not exist")
FileNotFoundError: File Data/AURSAD.h5 does not exist
ERROR: [guild] Trial 942b095459684db99ce76ca8ee4d49c6 exited with an error (1) - see log for details
