INFO: [guild] Running trial fb36c47a13114fa188512059fbeb2c3b: TABL:train (attention_constraint=None, attention_regularizer=None, binarize=no, dev=no, dimensionality=100, horizon=1, learning_rate=0.001, n_bl_layers=2, n_tabl_layers=1, optimizer=adam, projection_constraint=None, projection_regularizer=None, remote=no, window=100)
Traceback (most recent call last):
  File "/home/blez/Projects/anomaly_simulation/Zoo/Results/runs/fb36c47a13114fa188512059fbeb2c3b/.guild/sourcecode/TABL/train.py", line 78, in <module>
    _, train_y, _, test_y, train_generator, test_generator = aursad.get_dataset_generator(path=data_path,
  File "/home/blez/anaconda3/envs/anomaly_detection/lib/python3.8/site-packages/aursad/aursad.py", line 190, in get_dataset_generator
    data = load_dataset(path=path)
  File "/home/blez/anaconda3/envs/anomaly_detection/lib/python3.8/site-packages/aursad/utils.py", line 166, in load_dataset
    dataframe = pd.read_hdf(path)
  File "/home/blez/anaconda3/envs/anomaly_detection/lib/python3.8/site-packages/pandas/io/pytables.py", line 397, in read_hdf
    raise FileNotFoundError(f"File {path_or_buf} does not exist")
FileNotFoundError: File /Data/AURSAD.h5 does not exist
ERROR: [guild] Trial fb36c47a13114fa188512059fbeb2c3b exited with an error (1) - see log for details
INFO: [guild] Running trial e55b679464da49de99896139802bf664: TABL:train (attention_constraint=None, attention_regularizer=None, binarize=no, dev=no, dimensionality=80, horizon=1, learning_rate=0.001, n_bl_layers=2, n_tabl_layers=1, optimizer=adam, projection_constraint=None, projection_regularizer=None, remote=no, window=100)
Traceback (most recent call last):
  File "/home/blez/Projects/anomaly_simulation/Zoo/Results/runs/e55b679464da49de99896139802bf664/.guild/sourcecode/TABL/train.py", line 78, in <module>
    _, train_y, _, test_y, train_generator, test_generator = aursad.get_dataset_generator(path=data_path,
  File "/home/blez/anaconda3/envs/anomaly_detection/lib/python3.8/site-packages/aursad/aursad.py", line 190, in get_dataset_generator
    data = load_dataset(path=path)
  File "/home/blez/anaconda3/envs/anomaly_detection/lib/python3.8/site-packages/aursad/utils.py", line 166, in load_dataset
    dataframe = pd.read_hdf(path)
  File "/home/blez/anaconda3/envs/anomaly_detection/lib/python3.8/site-packages/pandas/io/pytables.py", line 397, in read_hdf
    raise FileNotFoundError(f"File {path_or_buf} does not exist")
FileNotFoundError: File /Data/AURSAD.h5 does not exist
ERROR: [guild] Trial e55b679464da49de99896139802bf664 exited with an error (1) - see log for details
INFO: [guild] Running trial 8c26de14c9344a6fbd1d87adf585353a: TABL:train (attention_constraint=None, attention_regularizer=None, binarize=no, dev=no, dimensionality=40, horizon=1, learning_rate=0.001, n_bl_layers=2, n_tabl_layers=1, optimizer=adam, projection_constraint=None, projection_regularizer=None, remote=no, window=100)
Traceback (most recent call last):
  File "/home/blez/Projects/anomaly_simulation/Zoo/Results/runs/8c26de14c9344a6fbd1d87adf585353a/.guild/sourcecode/TABL/train.py", line 78, in <module>
    _, train_y, _, test_y, train_generator, test_generator = aursad.get_dataset_generator(path=data_path,
  File "/home/blez/anaconda3/envs/anomaly_detection/lib/python3.8/site-packages/aursad/aursad.py", line 190, in get_dataset_generator
    data = load_dataset(path=path)
  File "/home/blez/anaconda3/envs/anomaly_detection/lib/python3.8/site-packages/aursad/utils.py", line 166, in load_dataset
    dataframe = pd.read_hdf(path)
  File "/home/blez/anaconda3/envs/anomaly_detection/lib/python3.8/site-packages/pandas/io/pytables.py", line 397, in read_hdf
    raise FileNotFoundError(f"File {path_or_buf} does not exist")
FileNotFoundError: File /Data/AURSAD.h5 does not exist
ERROR: [guild] Trial 8c26de14c9344a6fbd1d87adf585353a exited with an error (1) - see log for details
